[2025-09-04T13:35:48.005+0545] {local_task_job_runner.py:123} INFO - ::group::Pre task execution logs
[2025-09-04T13:35:48.011+0545] {taskinstance.py:2614} INFO - Dependencies all met for dep_context=non-requeueable deps ti=<TaskInstance: mlops_diabetes_pipeline.log_model_mlflow manual__2025-09-04T07:47:07.981399+00:00 [queued]>
[2025-09-04T13:35:48.014+0545] {taskinstance.py:2614} INFO - Dependencies all met for dep_context=requeueable deps ti=<TaskInstance: mlops_diabetes_pipeline.log_model_mlflow manual__2025-09-04T07:47:07.981399+00:00 [queued]>
[2025-09-04T13:35:48.014+0545] {taskinstance.py:2867} INFO - Starting attempt 2 of 2
[2025-09-04T13:35:48.026+0545] {taskinstance.py:2890} INFO - Executing <Task(PythonOperator): log_model_mlflow> on 2025-09-04 07:47:07.981399+00:00
[2025-09-04T13:35:48.037+0545] {standard_task_runner.py:72} INFO - Started process 17141 to run task
[2025-09-04T13:35:48.040+0545] {standard_task_runner.py:104} INFO - Running: ['airflow', 'tasks', 'run', 'mlops_diabetes_pipeline', 'log_model_mlflow', 'manual__2025-09-04T07:47:07.981399+00:00', '--job-id', '160', '--raw', '--subdir', 'DAGS_FOLDER/mlops_diabetes_pipeline.py', '--cfg-path', '/tmp/tmp6a9n_c_i']
[2025-09-04T13:35:48.041+0545] {standard_task_runner.py:105} INFO - Job 160: Subtask log_model_mlflow
[2025-09-04T13:35:48.068+0545] {task_command.py:467} INFO - Running <TaskInstance: mlops_diabetes_pipeline.log_model_mlflow manual__2025-09-04T07:47:07.981399+00:00 [running]> on host ashok-Nitro-ANV16-41
[2025-09-04T13:35:48.108+0545] {taskinstance.py:3134} INFO - Exporting env vars: AIRFLOW_CTX_DAG_EMAIL='koiralaashok02@gmail.com' AIRFLOW_CTX_DAG_OWNER='airflow' AIRFLOW_CTX_DAG_ID='mlops_diabetes_pipeline' AIRFLOW_CTX_TASK_ID='log_model_mlflow' AIRFLOW_CTX_EXECUTION_DATE='2025-09-04T07:47:07.981399+00:00' AIRFLOW_CTX_TRY_NUMBER='2' AIRFLOW_CTX_DAG_RUN_ID='manual__2025-09-04T07:47:07.981399+00:00'
[2025-09-04T13:35:48.109+0545] {logging_mixin.py:190} INFO - Task instance is in running state
[2025-09-04T13:35:48.109+0545] {logging_mixin.py:190} INFO -  Previous state of the Task instance: queued
[2025-09-04T13:35:48.109+0545] {logging_mixin.py:190} INFO - Current task name:log_model_mlflow state:running start_date:2025-09-04 07:50:48.012002+00:00
[2025-09-04T13:35:48.109+0545] {logging_mixin.py:190} INFO - Dag name:mlops_diabetes_pipeline and current dag run status:running
[2025-09-04T13:35:48.110+0545] {taskinstance.py:732} INFO - ::endgroup::
[2025-09-04T13:35:50.185+0545] {logging_mixin.py:190} WARNING - /home/ashok/miniconda3/envs/mysecondenvironment/lib/python3.8/site-packages/sklearn/metrics/_plot/confusion_matrix.py:136 UserWarning: Starting a Matplotlib GUI outside of the main thread will likely fail.
[2025-09-04T13:35:50.362+0545] {connectionpool.py:827} WARNING - Retrying (JitteredRetry(total=4, connect=4, read=5, redirect=5, status=5)) after connection broken by 'NewConnectionError('<urllib3.connection.HTTPConnection object at 0x778a24fe8070>: Failed to establish a new connection: [Errno 111] Connection refused')': /api/2.0/mlflow/experiments/get-by-name?experiment_name=diabetes_mlops_experiment
[2025-09-04T13:35:54.366+0545] {connectionpool.py:827} WARNING - Retrying (JitteredRetry(total=3, connect=3, read=5, redirect=5, status=5)) after connection broken by 'NewConnectionError('<urllib3.connection.HTTPConnection object at 0x778a24fe8670>: Failed to establish a new connection: [Errno 111] Connection refused')': /api/2.0/mlflow/experiments/get-by-name?experiment_name=diabetes_mlops_experiment
[2025-09-04T13:36:02.375+0545] {connectionpool.py:827} WARNING - Retrying (JitteredRetry(total=2, connect=2, read=5, redirect=5, status=5)) after connection broken by 'NewConnectionError('<urllib3.connection.HTTPConnection object at 0x778a24fe8820>: Failed to establish a new connection: [Errno 111] Connection refused')': /api/2.0/mlflow/experiments/get-by-name?experiment_name=diabetes_mlops_experiment
[2025-09-04T13:36:18.393+0545] {connectionpool.py:827} WARNING - Retrying (JitteredRetry(total=1, connect=1, read=5, redirect=5, status=5)) after connection broken by 'NewConnectionError('<urllib3.connection.HTTPConnection object at 0x778a24fe8b80>: Failed to establish a new connection: [Errno 111] Connection refused')': /api/2.0/mlflow/experiments/get-by-name?experiment_name=diabetes_mlops_experiment
[2025-09-04T13:36:50.427+0545] {connectionpool.py:827} WARNING - Retrying (JitteredRetry(total=0, connect=0, read=5, redirect=5, status=5)) after connection broken by 'NewConnectionError('<urllib3.connection.HTTPConnection object at 0x778a24fd0dc0>: Failed to establish a new connection: [Errno 111] Connection refused')': /api/2.0/mlflow/experiments/get-by-name?experiment_name=diabetes_mlops_experiment
[2025-09-04T13:36:50.428+0545] {taskinstance.py:3313} ERROR - Task failed with exception
Traceback (most recent call last):
  File "/home/ashok/miniconda3/envs/mysecondenvironment/lib/python3.8/site-packages/urllib3/connection.py", line 174, in _new_conn
    conn = connection.create_connection(
  File "/home/ashok/miniconda3/envs/mysecondenvironment/lib/python3.8/site-packages/urllib3/util/connection.py", line 95, in create_connection
    raise err
  File "/home/ashok/miniconda3/envs/mysecondenvironment/lib/python3.8/site-packages/urllib3/util/connection.py", line 85, in create_connection
    sock.connect(sa)
ConnectionRefusedError: [Errno 111] Connection refused

During handling of the above exception, another exception occurred:

Traceback (most recent call last):
  File "/home/ashok/miniconda3/envs/mysecondenvironment/lib/python3.8/site-packages/urllib3/connectionpool.py", line 716, in urlopen
    httplib_response = self._make_request(
  File "/home/ashok/miniconda3/envs/mysecondenvironment/lib/python3.8/site-packages/urllib3/connectionpool.py", line 416, in _make_request
    conn.request(method, url, **httplib_request_kw)
  File "/home/ashok/miniconda3/envs/mysecondenvironment/lib/python3.8/site-packages/urllib3/connection.py", line 244, in request
    super(HTTPConnection, self).request(method, url, body=body, headers=headers)
  File "/home/ashok/miniconda3/envs/mysecondenvironment/lib/python3.8/http/client.py", line 1256, in request
    self._send_request(method, url, body, headers, encode_chunked)
  File "/home/ashok/miniconda3/envs/mysecondenvironment/lib/python3.8/http/client.py", line 1302, in _send_request
    self.endheaders(body, encode_chunked=encode_chunked)
  File "/home/ashok/miniconda3/envs/mysecondenvironment/lib/python3.8/http/client.py", line 1251, in endheaders
    self._send_output(message_body, encode_chunked=encode_chunked)
  File "/home/ashok/miniconda3/envs/mysecondenvironment/lib/python3.8/http/client.py", line 1011, in _send_output
    self.send(msg)
  File "/home/ashok/miniconda3/envs/mysecondenvironment/lib/python3.8/http/client.py", line 951, in send
    self.connect()
  File "/home/ashok/miniconda3/envs/mysecondenvironment/lib/python3.8/site-packages/urllib3/connection.py", line 205, in connect
    conn = self._new_conn()
  File "/home/ashok/miniconda3/envs/mysecondenvironment/lib/python3.8/site-packages/urllib3/connection.py", line 186, in _new_conn
    raise NewConnectionError(
urllib3.exceptions.NewConnectionError: <urllib3.connection.HTTPConnection object at 0x778a24fd0c70>: Failed to establish a new connection: [Errno 111] Connection refused

During handling of the above exception, another exception occurred:

Traceback (most recent call last):
  File "/home/ashok/miniconda3/envs/mysecondenvironment/lib/python3.8/site-packages/requests/adapters.py", line 667, in send
    resp = conn.urlopen(
  File "/home/ashok/miniconda3/envs/mysecondenvironment/lib/python3.8/site-packages/urllib3/connectionpool.py", line 830, in urlopen
    return self.urlopen(
  File "/home/ashok/miniconda3/envs/mysecondenvironment/lib/python3.8/site-packages/urllib3/connectionpool.py", line 830, in urlopen
    return self.urlopen(
  File "/home/ashok/miniconda3/envs/mysecondenvironment/lib/python3.8/site-packages/urllib3/connectionpool.py", line 830, in urlopen
    return self.urlopen(
  [Previous line repeated 2 more times]
  File "/home/ashok/miniconda3/envs/mysecondenvironment/lib/python3.8/site-packages/urllib3/connectionpool.py", line 802, in urlopen
    retries = retries.increment(
  File "/home/ashok/miniconda3/envs/mysecondenvironment/lib/python3.8/site-packages/urllib3/util/retry.py", line 594, in increment
    raise MaxRetryError(_pool, url, error or ResponseError(cause))
urllib3.exceptions.MaxRetryError: HTTPConnectionPool(host='localhost', port=5000): Max retries exceeded with url: /api/2.0/mlflow/experiments/get-by-name?experiment_name=diabetes_mlops_experiment (Caused by NewConnectionError('<urllib3.connection.HTTPConnection object at 0x778a24fd0c70>: Failed to establish a new connection: [Errno 111] Connection refused'))

During handling of the above exception, another exception occurred:

Traceback (most recent call last):
  File "/home/ashok/miniconda3/envs/mysecondenvironment/lib/python3.8/site-packages/mlflow/utils/rest_utils.py", line 189, in http_request
    return _get_http_response_with_retries(
  File "/home/ashok/miniconda3/envs/mysecondenvironment/lib/python3.8/site-packages/mlflow/utils/request_utils.py", line 237, in _get_http_response_with_retries
    return session.request(method, url, allow_redirects=allow_redirects, **kwargs)
  File "/home/ashok/miniconda3/envs/mysecondenvironment/lib/python3.8/site-packages/requests/sessions.py", line 589, in request
    resp = self.send(prep, **send_kwargs)
  File "/home/ashok/miniconda3/envs/mysecondenvironment/lib/python3.8/site-packages/requests/sessions.py", line 703, in send
    r = adapter.send(request, **kwargs)
  File "/home/ashok/miniconda3/envs/mysecondenvironment/lib/python3.8/site-packages/requests/adapters.py", line 700, in send
    raise ConnectionError(e, request=request)
requests.exceptions.ConnectionError: HTTPConnectionPool(host='localhost', port=5000): Max retries exceeded with url: /api/2.0/mlflow/experiments/get-by-name?experiment_name=diabetes_mlops_experiment (Caused by NewConnectionError('<urllib3.connection.HTTPConnection object at 0x778a24fd0c70>: Failed to establish a new connection: [Errno 111] Connection refused'))

During handling of the above exception, another exception occurred:

Traceback (most recent call last):
  File "/home/ashok/miniconda3/envs/mysecondenvironment/lib/python3.8/site-packages/airflow/models/taskinstance.py", line 768, in _execute_task
    result = _execute_callable(context=context, **execute_callable_kwargs)
  File "/home/ashok/miniconda3/envs/mysecondenvironment/lib/python3.8/site-packages/airflow/models/taskinstance.py", line 734, in _execute_callable
    return ExecutionCallableRunner(
  File "/home/ashok/miniconda3/envs/mysecondenvironment/lib/python3.8/site-packages/airflow/utils/operator_helpers.py", line 252, in run
    return self.func(*args, **kwargs)
  File "/home/ashok/miniconda3/envs/mysecondenvironment/lib/python3.8/site-packages/airflow/models/baseoperator.py", line 424, in wrapper
    return func(self, *args, **kwargs)
  File "/home/ashok/miniconda3/envs/mysecondenvironment/lib/python3.8/site-packages/airflow/operators/python.py", line 238, in execute
    return_value = self.execute_callable()
  File "/home/ashok/miniconda3/envs/mysecondenvironment/lib/python3.8/site-packages/airflow/operators/python.py", line 256, in execute_callable
    return runner.run(*self.op_args, **self.op_kwargs)
  File "/home/ashok/miniconda3/envs/mysecondenvironment/lib/python3.8/site-packages/airflow/utils/operator_helpers.py", line 252, in run
    return self.func(*args, **kwargs)
  File "/home/ashok/mlops_project/airflow/dags/mlops_diabetes_pipeline.py", line 442, in log_model_mlflow
    mlflow.set_experiment(MLFLOW_EXPERIMENT)
  File "/home/ashok/miniconda3/envs/mysecondenvironment/lib/python3.8/site-packages/mlflow/tracking/fluent.py", line 145, in set_experiment
    experiment = client.get_experiment_by_name(experiment_name)
  File "/home/ashok/miniconda3/envs/mysecondenvironment/lib/python3.8/site-packages/mlflow/tracking/client.py", line 1256, in get_experiment_by_name
    return self._tracking_client.get_experiment_by_name(name)
  File "/home/ashok/miniconda3/envs/mysecondenvironment/lib/python3.8/site-packages/mlflow/tracking/_tracking_service/client.py", line 501, in get_experiment_by_name
    return self.store.get_experiment_by_name(name)
  File "/home/ashok/miniconda3/envs/mysecondenvironment/lib/python3.8/site-packages/mlflow/store/tracking/rest_store.py", line 519, in get_experiment_by_name
    response_proto = self._call_endpoint(GetExperimentByName, req_body)
  File "/home/ashok/miniconda3/envs/mysecondenvironment/lib/python3.8/site-packages/mlflow/store/tracking/rest_store.py", line 82, in _call_endpoint
    return call_endpoint(self.get_host_creds(), endpoint, method, json_body, response_proto)
  File "/home/ashok/miniconda3/envs/mysecondenvironment/lib/python3.8/site-packages/mlflow/utils/rest_utils.py", line 365, in call_endpoint
    response = http_request(**call_kwargs)
  File "/home/ashok/miniconda3/envs/mysecondenvironment/lib/python3.8/site-packages/mlflow/utils/rest_utils.py", line 212, in http_request
    raise MlflowException(f"API request to {url} failed with exception {e}")
mlflow.exceptions.MlflowException: API request to http://localhost:5000/api/2.0/mlflow/experiments/get-by-name failed with exception HTTPConnectionPool(host='localhost', port=5000): Max retries exceeded with url: /api/2.0/mlflow/experiments/get-by-name?experiment_name=diabetes_mlops_experiment (Caused by NewConnectionError('<urllib3.connection.HTTPConnection object at 0x778a24fd0c70>: Failed to establish a new connection: [Errno 111] Connection refused'))
[2025-09-04T13:36:50.435+0545] {logging_mixin.py:190} INFO - Task instance in failure state
[2025-09-04T13:36:50.435+0545] {logging_mixin.py:190} INFO - Task start:2025-09-04 07:50:48.012002+00:00 end:2025-09-04 07:51:50.434718+00:00 duration:62.422716
[2025-09-04T13:36:50.435+0545] {logging_mixin.py:190} INFO - Task:<Task(PythonOperator): log_model_mlflow> dag:<DAG: mlops_diabetes_pipeline> dagrun:<DagRun mlops_diabetes_pipeline @ 2025-09-04 07:47:07.981399+00:00: manual__2025-09-04T07:47:07.981399+00:00, state:running, queued_at: 2025-09-04 07:47:07.988104+00:00. externally triggered: True>
[2025-09-04T13:36:50.435+0545] {logging_mixin.py:190} INFO - Failure caused by API request to http://localhost:5000/api/2.0/mlflow/experiments/get-by-name failed with exception HTTPConnectionPool(host='localhost', port=5000): Max retries exceeded with url: /api/2.0/mlflow/experiments/get-by-name?experiment_name=diabetes_mlops_experiment (Caused by NewConnectionError('<urllib3.connection.HTTPConnection object at 0x778a24fd0c70>: Failed to establish a new connection: [Errno 111] Connection refused'))
[2025-09-04T13:36:50.435+0545] {taskinstance.py:1226} INFO - Marking task as FAILED. dag_id=mlops_diabetes_pipeline, task_id=log_model_mlflow, run_id=manual__2025-09-04T07:47:07.981399+00:00, execution_date=20250904T074707, start_date=20250904T075048, end_date=20250904T075150
[2025-09-04T13:36:50.442+0545] {base.py:84} INFO - Retrieving connection 'smtp_default'
[2025-09-04T13:36:50.442+0545] {email.py:272} INFO - Email alerting: attempt 1
[2025-09-04T13:37:22.377+0545] {email.py:283} INFO - Sent an alert email to ['koiralaashok02@gmail.com']
[2025-09-04T13:37:24.313+0545] {taskinstance.py:341} INFO - ::group::Post task execution logs
[2025-09-04T13:37:24.313+0545] {standard_task_runner.py:124} ERROR - Failed to execute job 160 for task log_model_mlflow (API request to http://localhost:5000/api/2.0/mlflow/experiments/get-by-name failed with exception HTTPConnectionPool(host='localhost', port=5000): Max retries exceeded with url: /api/2.0/mlflow/experiments/get-by-name?experiment_name=diabetes_mlops_experiment (Caused by NewConnectionError('<urllib3.connection.HTTPConnection object at 0x778a24fd0c70>: Failed to establish a new connection: [Errno 111] Connection refused')); 17141)
Traceback (most recent call last):
  File "/home/ashok/miniconda3/envs/mysecondenvironment/lib/python3.8/site-packages/urllib3/connection.py", line 174, in _new_conn
    conn = connection.create_connection(
  File "/home/ashok/miniconda3/envs/mysecondenvironment/lib/python3.8/site-packages/urllib3/util/connection.py", line 95, in create_connection
    raise err
  File "/home/ashok/miniconda3/envs/mysecondenvironment/lib/python3.8/site-packages/urllib3/util/connection.py", line 85, in create_connection
    sock.connect(sa)
ConnectionRefusedError: [Errno 111] Connection refused

During handling of the above exception, another exception occurred:

Traceback (most recent call last):
  File "/home/ashok/miniconda3/envs/mysecondenvironment/lib/python3.8/site-packages/urllib3/connectionpool.py", line 716, in urlopen
    httplib_response = self._make_request(
  File "/home/ashok/miniconda3/envs/mysecondenvironment/lib/python3.8/site-packages/urllib3/connectionpool.py", line 416, in _make_request
    conn.request(method, url, **httplib_request_kw)
  File "/home/ashok/miniconda3/envs/mysecondenvironment/lib/python3.8/site-packages/urllib3/connection.py", line 244, in request
    super(HTTPConnection, self).request(method, url, body=body, headers=headers)
  File "/home/ashok/miniconda3/envs/mysecondenvironment/lib/python3.8/http/client.py", line 1256, in request
    self._send_request(method, url, body, headers, encode_chunked)
  File "/home/ashok/miniconda3/envs/mysecondenvironment/lib/python3.8/http/client.py", line 1302, in _send_request
    self.endheaders(body, encode_chunked=encode_chunked)
  File "/home/ashok/miniconda3/envs/mysecondenvironment/lib/python3.8/http/client.py", line 1251, in endheaders
    self._send_output(message_body, encode_chunked=encode_chunked)
  File "/home/ashok/miniconda3/envs/mysecondenvironment/lib/python3.8/http/client.py", line 1011, in _send_output
    self.send(msg)
  File "/home/ashok/miniconda3/envs/mysecondenvironment/lib/python3.8/http/client.py", line 951, in send
    self.connect()
  File "/home/ashok/miniconda3/envs/mysecondenvironment/lib/python3.8/site-packages/urllib3/connection.py", line 205, in connect
    conn = self._new_conn()
  File "/home/ashok/miniconda3/envs/mysecondenvironment/lib/python3.8/site-packages/urllib3/connection.py", line 186, in _new_conn
    raise NewConnectionError(
urllib3.exceptions.NewConnectionError: <urllib3.connection.HTTPConnection object at 0x778a24fd0c70>: Failed to establish a new connection: [Errno 111] Connection refused

During handling of the above exception, another exception occurred:

Traceback (most recent call last):
  File "/home/ashok/miniconda3/envs/mysecondenvironment/lib/python3.8/site-packages/requests/adapters.py", line 667, in send
    resp = conn.urlopen(
  File "/home/ashok/miniconda3/envs/mysecondenvironment/lib/python3.8/site-packages/urllib3/connectionpool.py", line 830, in urlopen
    return self.urlopen(
  File "/home/ashok/miniconda3/envs/mysecondenvironment/lib/python3.8/site-packages/urllib3/connectionpool.py", line 830, in urlopen
    return self.urlopen(
  File "/home/ashok/miniconda3/envs/mysecondenvironment/lib/python3.8/site-packages/urllib3/connectionpool.py", line 830, in urlopen
    return self.urlopen(
  [Previous line repeated 2 more times]
  File "/home/ashok/miniconda3/envs/mysecondenvironment/lib/python3.8/site-packages/urllib3/connectionpool.py", line 802, in urlopen
    retries = retries.increment(
  File "/home/ashok/miniconda3/envs/mysecondenvironment/lib/python3.8/site-packages/urllib3/util/retry.py", line 594, in increment
    raise MaxRetryError(_pool, url, error or ResponseError(cause))
urllib3.exceptions.MaxRetryError: HTTPConnectionPool(host='localhost', port=5000): Max retries exceeded with url: /api/2.0/mlflow/experiments/get-by-name?experiment_name=diabetes_mlops_experiment (Caused by NewConnectionError('<urllib3.connection.HTTPConnection object at 0x778a24fd0c70>: Failed to establish a new connection: [Errno 111] Connection refused'))

During handling of the above exception, another exception occurred:

Traceback (most recent call last):
  File "/home/ashok/miniconda3/envs/mysecondenvironment/lib/python3.8/site-packages/mlflow/utils/rest_utils.py", line 189, in http_request
    return _get_http_response_with_retries(
  File "/home/ashok/miniconda3/envs/mysecondenvironment/lib/python3.8/site-packages/mlflow/utils/request_utils.py", line 237, in _get_http_response_with_retries
    return session.request(method, url, allow_redirects=allow_redirects, **kwargs)
  File "/home/ashok/miniconda3/envs/mysecondenvironment/lib/python3.8/site-packages/requests/sessions.py", line 589, in request
    resp = self.send(prep, **send_kwargs)
  File "/home/ashok/miniconda3/envs/mysecondenvironment/lib/python3.8/site-packages/requests/sessions.py", line 703, in send
    r = adapter.send(request, **kwargs)
  File "/home/ashok/miniconda3/envs/mysecondenvironment/lib/python3.8/site-packages/requests/adapters.py", line 700, in send
    raise ConnectionError(e, request=request)
requests.exceptions.ConnectionError: HTTPConnectionPool(host='localhost', port=5000): Max retries exceeded with url: /api/2.0/mlflow/experiments/get-by-name?experiment_name=diabetes_mlops_experiment (Caused by NewConnectionError('<urllib3.connection.HTTPConnection object at 0x778a24fd0c70>: Failed to establish a new connection: [Errno 111] Connection refused'))

During handling of the above exception, another exception occurred:

Traceback (most recent call last):
  File "/home/ashok/miniconda3/envs/mysecondenvironment/lib/python3.8/site-packages/airflow/task/task_runner/standard_task_runner.py", line 117, in _start_by_fork
    ret = args.func(args, dag=self.dag)
  File "/home/ashok/miniconda3/envs/mysecondenvironment/lib/python3.8/site-packages/airflow/cli/cli_config.py", line 49, in command
    return func(*args, **kwargs)
  File "/home/ashok/miniconda3/envs/mysecondenvironment/lib/python3.8/site-packages/airflow/utils/cli.py", line 116, in wrapper
    return f(*args, **kwargs)
  File "/home/ashok/miniconda3/envs/mysecondenvironment/lib/python3.8/site-packages/airflow/cli/commands/task_command.py", line 483, in task_run
    task_return_code = _run_task_by_selected_method(args, _dag, ti)
  File "/home/ashok/miniconda3/envs/mysecondenvironment/lib/python3.8/site-packages/airflow/cli/commands/task_command.py", line 256, in _run_task_by_selected_method
    return _run_raw_task(args, ti)
  File "/home/ashok/miniconda3/envs/mysecondenvironment/lib/python3.8/site-packages/airflow/cli/commands/task_command.py", line 341, in _run_raw_task
    return ti._run_raw_task(
  File "/home/ashok/miniconda3/envs/mysecondenvironment/lib/python3.8/site-packages/airflow/utils/session.py", line 97, in wrapper
    return func(*args, session=session, **kwargs)
  File "/home/ashok/miniconda3/envs/mysecondenvironment/lib/python3.8/site-packages/airflow/models/taskinstance.py", line 3006, in _run_raw_task
    return _run_raw_task(
  File "/home/ashok/miniconda3/envs/mysecondenvironment/lib/python3.8/site-packages/airflow/models/taskinstance.py", line 274, in _run_raw_task
    TaskInstance._execute_task_with_callbacks(
  File "/home/ashok/miniconda3/envs/mysecondenvironment/lib/python3.8/site-packages/airflow/models/taskinstance.py", line 3161, in _execute_task_with_callbacks
    result = self._execute_task(context, task_orig)
  File "/home/ashok/miniconda3/envs/mysecondenvironment/lib/python3.8/site-packages/airflow/models/taskinstance.py", line 3185, in _execute_task
    return _execute_task(self, context, task_orig)
  File "/home/ashok/miniconda3/envs/mysecondenvironment/lib/python3.8/site-packages/airflow/models/taskinstance.py", line 768, in _execute_task
    result = _execute_callable(context=context, **execute_callable_kwargs)
  File "/home/ashok/miniconda3/envs/mysecondenvironment/lib/python3.8/site-packages/airflow/models/taskinstance.py", line 734, in _execute_callable
    return ExecutionCallableRunner(
  File "/home/ashok/miniconda3/envs/mysecondenvironment/lib/python3.8/site-packages/airflow/utils/operator_helpers.py", line 252, in run
    return self.func(*args, **kwargs)
  File "/home/ashok/miniconda3/envs/mysecondenvironment/lib/python3.8/site-packages/airflow/models/baseoperator.py", line 424, in wrapper
    return func(self, *args, **kwargs)
  File "/home/ashok/miniconda3/envs/mysecondenvironment/lib/python3.8/site-packages/airflow/operators/python.py", line 238, in execute
    return_value = self.execute_callable()
  File "/home/ashok/miniconda3/envs/mysecondenvironment/lib/python3.8/site-packages/airflow/operators/python.py", line 256, in execute_callable
    return runner.run(*self.op_args, **self.op_kwargs)
  File "/home/ashok/miniconda3/envs/mysecondenvironment/lib/python3.8/site-packages/airflow/utils/operator_helpers.py", line 252, in run
    return self.func(*args, **kwargs)
  File "/home/ashok/mlops_project/airflow/dags/mlops_diabetes_pipeline.py", line 442, in log_model_mlflow
    mlflow.set_experiment(MLFLOW_EXPERIMENT)
  File "/home/ashok/miniconda3/envs/mysecondenvironment/lib/python3.8/site-packages/mlflow/tracking/fluent.py", line 145, in set_experiment
    experiment = client.get_experiment_by_name(experiment_name)
  File "/home/ashok/miniconda3/envs/mysecondenvironment/lib/python3.8/site-packages/mlflow/tracking/client.py", line 1256, in get_experiment_by_name
    return self._tracking_client.get_experiment_by_name(name)
  File "/home/ashok/miniconda3/envs/mysecondenvironment/lib/python3.8/site-packages/mlflow/tracking/_tracking_service/client.py", line 501, in get_experiment_by_name
    return self.store.get_experiment_by_name(name)
  File "/home/ashok/miniconda3/envs/mysecondenvironment/lib/python3.8/site-packages/mlflow/store/tracking/rest_store.py", line 519, in get_experiment_by_name
    response_proto = self._call_endpoint(GetExperimentByName, req_body)
  File "/home/ashok/miniconda3/envs/mysecondenvironment/lib/python3.8/site-packages/mlflow/store/tracking/rest_store.py", line 82, in _call_endpoint
    return call_endpoint(self.get_host_creds(), endpoint, method, json_body, response_proto)
  File "/home/ashok/miniconda3/envs/mysecondenvironment/lib/python3.8/site-packages/mlflow/utils/rest_utils.py", line 365, in call_endpoint
    response = http_request(**call_kwargs)
  File "/home/ashok/miniconda3/envs/mysecondenvironment/lib/python3.8/site-packages/mlflow/utils/rest_utils.py", line 212, in http_request
    raise MlflowException(f"API request to {url} failed with exception {e}")
mlflow.exceptions.MlflowException: API request to http://localhost:5000/api/2.0/mlflow/experiments/get-by-name failed with exception HTTPConnectionPool(host='localhost', port=5000): Max retries exceeded with url: /api/2.0/mlflow/experiments/get-by-name?experiment_name=diabetes_mlops_experiment (Caused by NewConnectionError('<urllib3.connection.HTTPConnection object at 0x778a24fd0c70>: Failed to establish a new connection: [Errno 111] Connection refused'))
[2025-09-04T13:37:24.464+0545] {local_task_job_runner.py:266} INFO - Task exited with return code 1
[2025-09-04T13:37:24.475+0545] {taskinstance.py:3901} INFO - 0 downstream tasks scheduled from follow-on schedule check
[2025-09-04T13:37:24.486+0545] {local_task_job_runner.py:245} INFO - ::endgroup::
