[2025-09-04T14:01:24.184+0545] {local_task_job_runner.py:123} INFO - ::group::Pre task execution logs
[2025-09-04T14:01:24.191+0545] {taskinstance.py:2614} INFO - Dependencies all met for dep_context=non-requeueable deps ti=<TaskInstance: start_diabetes_stack.docker_exec manual__2025-09-04T08:15:15.963259+00:00 [queued]>
[2025-09-04T14:01:24.195+0545] {taskinstance.py:2614} INFO - Dependencies all met for dep_context=requeueable deps ti=<TaskInstance: start_diabetes_stack.docker_exec manual__2025-09-04T08:15:15.963259+00:00 [queued]>
[2025-09-04T14:01:24.195+0545] {taskinstance.py:2867} INFO - Starting attempt 2 of 2
[2025-09-04T14:01:24.208+0545] {taskinstance.py:2890} INFO - Executing <Task(BashOperator): docker_exec> on 2025-09-04 08:15:15.963259+00:00
[2025-09-04T14:01:24.215+0545] {standard_task_runner.py:72} INFO - Started process 31095 to run task
[2025-09-04T14:01:24.218+0545] {standard_task_runner.py:104} INFO - Running: ['airflow', 'tasks', 'run', 'start_diabetes_stack', 'docker_exec', 'manual__2025-09-04T08:15:15.963259+00:00', '--job-id', '183', '--raw', '--subdir', 'DAGS_FOLDER/bash_operator.py', '--cfg-path', '/tmp/tmpxdygv73h']
[2025-09-04T14:01:24.219+0545] {standard_task_runner.py:105} INFO - Job 183: Subtask docker_exec
[2025-09-04T14:01:24.243+0545] {task_command.py:467} INFO - Running <TaskInstance: start_diabetes_stack.docker_exec manual__2025-09-04T08:15:15.963259+00:00 [running]> on host ashok-Nitro-ANV16-41
[2025-09-04T14:01:24.274+0545] {taskinstance.py:3134} INFO - Exporting env vars: AIRFLOW_CTX_DAG_OWNER='ashok' AIRFLOW_CTX_DAG_ID='start_diabetes_stack' AIRFLOW_CTX_TASK_ID='docker_exec' AIRFLOW_CTX_EXECUTION_DATE='2025-09-04T08:15:15.963259+00:00' AIRFLOW_CTX_TRY_NUMBER='2' AIRFLOW_CTX_DAG_RUN_ID='manual__2025-09-04T08:15:15.963259+00:00'
[2025-09-04T14:01:24.275+0545] {logging_mixin.py:190} INFO - Task instance is in running state
[2025-09-04T14:01:24.275+0545] {logging_mixin.py:190} INFO -  Previous state of the Task instance: queued
[2025-09-04T14:01:24.275+0545] {logging_mixin.py:190} INFO - Current task name:docker_exec state:running start_date:2025-09-04 08:16:24.192232+00:00
[2025-09-04T14:01:24.275+0545] {logging_mixin.py:190} INFO - Dag name:start_diabetes_stack and current dag run status:running
[2025-09-04T14:01:24.275+0545] {taskinstance.py:732} INFO - ::endgroup::
[2025-09-04T14:01:24.275+0545] {subprocess.py:78} INFO - Tmp dir root location: /tmp
[2025-09-04T14:01:24.276+0545] {subprocess.py:88} INFO - Running command: ['/usr/bin/bash', '-c', 'docker exec -i mcs_container mariadb -u root -p"root" -h 127.0.0.1 -P 3306 mydb -e "SELECT 1;"']
[2025-09-04T14:01:24.286+0545] {subprocess.py:99} INFO - Output:
[2025-09-04T14:01:24.345+0545] {subprocess.py:106} INFO - ERROR 1698 (28000): Access denied for user 'root'@'localhost'
[2025-09-04T14:01:24.348+0545] {subprocess.py:110} INFO - Command exited with return code 1
[2025-09-04T14:01:24.352+0545] {taskinstance.py:3313} ERROR - Task failed with exception
Traceback (most recent call last):
  File "/home/ashok/miniconda3/envs/mysecondenvironment/lib/python3.8/site-packages/airflow/models/taskinstance.py", line 768, in _execute_task
    result = _execute_callable(context=context, **execute_callable_kwargs)
  File "/home/ashok/miniconda3/envs/mysecondenvironment/lib/python3.8/site-packages/airflow/models/taskinstance.py", line 734, in _execute_callable
    return ExecutionCallableRunner(
  File "/home/ashok/miniconda3/envs/mysecondenvironment/lib/python3.8/site-packages/airflow/utils/operator_helpers.py", line 252, in run
    return self.func(*args, **kwargs)
  File "/home/ashok/miniconda3/envs/mysecondenvironment/lib/python3.8/site-packages/airflow/models/baseoperator.py", line 424, in wrapper
    return func(self, *args, **kwargs)
  File "/home/ashok/miniconda3/envs/mysecondenvironment/lib/python3.8/site-packages/airflow/operators/bash.py", line 276, in execute
    raise AirflowException(
airflow.exceptions.AirflowException: Bash command failed. The command returned a non-zero exit code 1.
[2025-09-04T14:01:24.353+0545] {logging_mixin.py:190} INFO - Task instance in failure state
[2025-09-04T14:01:24.353+0545] {logging_mixin.py:190} INFO - Task start:2025-09-04 08:16:24.192232+00:00 end:2025-09-04 08:16:24.353302+00:00 duration:0.16107
[2025-09-04T14:01:24.353+0545] {logging_mixin.py:190} INFO - Task:<Task(BashOperator): docker_exec> dag:<DAG: start_diabetes_stack> dagrun:<DagRun start_diabetes_stack @ 2025-09-04 08:15:15.963259+00:00: manual__2025-09-04T08:15:15.963259+00:00, state:running, queued_at: 2025-09-04 08:15:15.983738+00:00. externally triggered: True>
[2025-09-04T14:01:24.353+0545] {logging_mixin.py:190} INFO - Failure caused by Bash command failed. The command returned a non-zero exit code 1.
[2025-09-04T14:01:24.353+0545] {taskinstance.py:1226} INFO - Marking task as FAILED. dag_id=start_diabetes_stack, task_id=docker_exec, run_id=manual__2025-09-04T08:15:15.963259+00:00, execution_date=20250904T081515, start_date=20250904T081624, end_date=20250904T081624
[2025-09-04T14:01:24.374+0545] {taskinstance.py:341} INFO - ::group::Post task execution logs
[2025-09-04T14:01:24.375+0545] {standard_task_runner.py:124} ERROR - Failed to execute job 183 for task docker_exec (Bash command failed. The command returned a non-zero exit code 1.; 31095)
Traceback (most recent call last):
  File "/home/ashok/miniconda3/envs/mysecondenvironment/lib/python3.8/site-packages/airflow/task/task_runner/standard_task_runner.py", line 117, in _start_by_fork
    ret = args.func(args, dag=self.dag)
  File "/home/ashok/miniconda3/envs/mysecondenvironment/lib/python3.8/site-packages/airflow/cli/cli_config.py", line 49, in command
    return func(*args, **kwargs)
  File "/home/ashok/miniconda3/envs/mysecondenvironment/lib/python3.8/site-packages/airflow/utils/cli.py", line 116, in wrapper
    return f(*args, **kwargs)
  File "/home/ashok/miniconda3/envs/mysecondenvironment/lib/python3.8/site-packages/airflow/cli/commands/task_command.py", line 483, in task_run
    task_return_code = _run_task_by_selected_method(args, _dag, ti)
  File "/home/ashok/miniconda3/envs/mysecondenvironment/lib/python3.8/site-packages/airflow/cli/commands/task_command.py", line 256, in _run_task_by_selected_method
    return _run_raw_task(args, ti)
  File "/home/ashok/miniconda3/envs/mysecondenvironment/lib/python3.8/site-packages/airflow/cli/commands/task_command.py", line 341, in _run_raw_task
    return ti._run_raw_task(
  File "/home/ashok/miniconda3/envs/mysecondenvironment/lib/python3.8/site-packages/airflow/utils/session.py", line 97, in wrapper
    return func(*args, session=session, **kwargs)
  File "/home/ashok/miniconda3/envs/mysecondenvironment/lib/python3.8/site-packages/airflow/models/taskinstance.py", line 3006, in _run_raw_task
    return _run_raw_task(
  File "/home/ashok/miniconda3/envs/mysecondenvironment/lib/python3.8/site-packages/airflow/models/taskinstance.py", line 274, in _run_raw_task
    TaskInstance._execute_task_with_callbacks(
  File "/home/ashok/miniconda3/envs/mysecondenvironment/lib/python3.8/site-packages/airflow/models/taskinstance.py", line 3161, in _execute_task_with_callbacks
    result = self._execute_task(context, task_orig)
  File "/home/ashok/miniconda3/envs/mysecondenvironment/lib/python3.8/site-packages/airflow/models/taskinstance.py", line 3185, in _execute_task
    return _execute_task(self, context, task_orig)
  File "/home/ashok/miniconda3/envs/mysecondenvironment/lib/python3.8/site-packages/airflow/models/taskinstance.py", line 768, in _execute_task
    result = _execute_callable(context=context, **execute_callable_kwargs)
  File "/home/ashok/miniconda3/envs/mysecondenvironment/lib/python3.8/site-packages/airflow/models/taskinstance.py", line 734, in _execute_callable
    return ExecutionCallableRunner(
  File "/home/ashok/miniconda3/envs/mysecondenvironment/lib/python3.8/site-packages/airflow/utils/operator_helpers.py", line 252, in run
    return self.func(*args, **kwargs)
  File "/home/ashok/miniconda3/envs/mysecondenvironment/lib/python3.8/site-packages/airflow/models/baseoperator.py", line 424, in wrapper
    return func(self, *args, **kwargs)
  File "/home/ashok/miniconda3/envs/mysecondenvironment/lib/python3.8/site-packages/airflow/operators/bash.py", line 276, in execute
    raise AirflowException(
airflow.exceptions.AirflowException: Bash command failed. The command returned a non-zero exit code 1.
[2025-09-04T14:01:24.390+0545] {local_task_job_runner.py:266} INFO - Task exited with return code 1
[2025-09-04T14:01:24.398+0545] {taskinstance.py:3901} INFO - 0 downstream tasks scheduled from follow-on schedule check
[2025-09-04T14:01:24.407+0545] {local_task_job_runner.py:245} INFO - ::endgroup::
