[2025-09-05T11:42:35.074+0545] {local_task_job_runner.py:123} INFO - ::group::Pre task execution logs
[2025-09-05T11:42:35.083+0545] {taskinstance.py:2614} INFO - Dependencies all met for dep_context=non-requeueable deps ti=<TaskInstance: mlops_diabetes_pipeline.log_model_mlflow manual__2025-09-05T05:56:45.402705+00:00 [queued]>
[2025-09-05T11:42:35.087+0545] {taskinstance.py:2614} INFO - Dependencies all met for dep_context=requeueable deps ti=<TaskInstance: mlops_diabetes_pipeline.log_model_mlflow manual__2025-09-05T05:56:45.402705+00:00 [queued]>
[2025-09-05T11:42:35.087+0545] {taskinstance.py:2867} INFO - Starting attempt 1 of 2
[2025-09-05T11:42:35.103+0545] {taskinstance.py:2890} INFO - Executing <Task(PythonOperator): log_model_mlflow> on 2025-09-05 05:56:45.402705+00:00
[2025-09-05T11:42:35.121+0545] {standard_task_runner.py:72} INFO - Started process 47600 to run task
[2025-09-05T11:42:35.125+0545] {standard_task_runner.py:104} INFO - Running: ['airflow', 'tasks', 'run', 'mlops_diabetes_pipeline', 'log_model_mlflow', 'manual__2025-09-05T05:56:45.402705+00:00', '--job-id', '380', '--raw', '--subdir', 'DAGS_FOLDER/mlops_diabetes_pipeline.py', '--cfg-path', '/tmp/tmp5s76z264']
[2025-09-05T11:42:35.126+0545] {standard_task_runner.py:105} INFO - Job 380: Subtask log_model_mlflow
[2025-09-05T11:42:35.158+0545] {task_command.py:467} INFO - Running <TaskInstance: mlops_diabetes_pipeline.log_model_mlflow manual__2025-09-05T05:56:45.402705+00:00 [running]> on host ashok-Nitro-ANV16-41
[2025-09-05T11:42:35.210+0545] {taskinstance.py:3134} INFO - Exporting env vars: AIRFLOW_CTX_DAG_EMAIL='koiralaashok02@gmail.com' AIRFLOW_CTX_DAG_OWNER='airflow' AIRFLOW_CTX_DAG_ID='mlops_diabetes_pipeline' AIRFLOW_CTX_TASK_ID='log_model_mlflow' AIRFLOW_CTX_EXECUTION_DATE='2025-09-05T05:56:45.402705+00:00' AIRFLOW_CTX_TRY_NUMBER='1' AIRFLOW_CTX_DAG_RUN_ID='manual__2025-09-05T05:56:45.402705+00:00'
[2025-09-05T11:42:35.211+0545] {logging_mixin.py:190} INFO - Task instance is in running state
[2025-09-05T11:42:35.212+0545] {logging_mixin.py:190} INFO -  Previous state of the Task instance: queued
[2025-09-05T11:42:35.212+0545] {logging_mixin.py:190} INFO - Current task name:log_model_mlflow state:running start_date:2025-09-05 05:57:35.083486+00:00
[2025-09-05T11:42:35.212+0545] {logging_mixin.py:190} INFO - Dag name:mlops_diabetes_pipeline and current dag run status:running
[2025-09-05T11:42:35.212+0545] {taskinstance.py:732} INFO - ::endgroup::
[2025-09-05T11:42:35.622+0545] {logging_mixin.py:190} WARNING - /home/ashok/miniconda3/envs/mysecondenvironment/lib/python3.8/site-packages/sklearn/metrics/_plot/confusion_matrix.py:136 UserWarning: Starting a Matplotlib GUI outside of the main thread will likely fail.
[2025-09-05T11:43:36.008+0545] {taskinstance.py:3313} ERROR - Task failed with exception
Traceback (most recent call last):
  File "/home/ashok/miniconda3/envs/mysecondenvironment/lib/python3.8/site-packages/requests/adapters.py", line 667, in send
    resp = conn.urlopen(
  File "/home/ashok/miniconda3/envs/mysecondenvironment/lib/python3.8/site-packages/urllib3/connectionpool.py", line 897, in urlopen
    return self.urlopen(
  File "/home/ashok/miniconda3/envs/mysecondenvironment/lib/python3.8/site-packages/urllib3/connectionpool.py", line 897, in urlopen
    return self.urlopen(
  File "/home/ashok/miniconda3/envs/mysecondenvironment/lib/python3.8/site-packages/urllib3/connectionpool.py", line 897, in urlopen
    return self.urlopen(
  [Previous line repeated 2 more times]
  File "/home/ashok/miniconda3/envs/mysecondenvironment/lib/python3.8/site-packages/urllib3/connectionpool.py", line 887, in urlopen
    retries = retries.increment(method, url, response=response, _pool=self)
  File "/home/ashok/miniconda3/envs/mysecondenvironment/lib/python3.8/site-packages/urllib3/util/retry.py", line 594, in increment
    raise MaxRetryError(_pool, url, error or ResponseError(cause))
urllib3.exceptions.MaxRetryError: HTTPConnectionPool(host='localhost', port=5000): Max retries exceeded with url: /api/2.0/mlflow/experiments/get-by-name?experiment_name=diabetes_mlops_experiment (Caused by ResponseError('too many 500 error responses'))

During handling of the above exception, another exception occurred:

Traceback (most recent call last):
  File "/home/ashok/miniconda3/envs/mysecondenvironment/lib/python3.8/site-packages/mlflow/utils/rest_utils.py", line 189, in http_request
    return _get_http_response_with_retries(
  File "/home/ashok/miniconda3/envs/mysecondenvironment/lib/python3.8/site-packages/mlflow/utils/request_utils.py", line 237, in _get_http_response_with_retries
    return session.request(method, url, allow_redirects=allow_redirects, **kwargs)
  File "/home/ashok/miniconda3/envs/mysecondenvironment/lib/python3.8/site-packages/requests/sessions.py", line 589, in request
    resp = self.send(prep, **send_kwargs)
  File "/home/ashok/miniconda3/envs/mysecondenvironment/lib/python3.8/site-packages/requests/sessions.py", line 703, in send
    r = adapter.send(request, **kwargs)
  File "/home/ashok/miniconda3/envs/mysecondenvironment/lib/python3.8/site-packages/requests/adapters.py", line 691, in send
    raise RetryError(e, request=request)
requests.exceptions.RetryError: HTTPConnectionPool(host='localhost', port=5000): Max retries exceeded with url: /api/2.0/mlflow/experiments/get-by-name?experiment_name=diabetes_mlops_experiment (Caused by ResponseError('too many 500 error responses'))

During handling of the above exception, another exception occurred:

Traceback (most recent call last):
  File "/home/ashok/miniconda3/envs/mysecondenvironment/lib/python3.8/site-packages/airflow/models/taskinstance.py", line 768, in _execute_task
    result = _execute_callable(context=context, **execute_callable_kwargs)
  File "/home/ashok/miniconda3/envs/mysecondenvironment/lib/python3.8/site-packages/airflow/models/taskinstance.py", line 734, in _execute_callable
    return ExecutionCallableRunner(
  File "/home/ashok/miniconda3/envs/mysecondenvironment/lib/python3.8/site-packages/airflow/utils/operator_helpers.py", line 252, in run
    return self.func(*args, **kwargs)
  File "/home/ashok/miniconda3/envs/mysecondenvironment/lib/python3.8/site-packages/airflow/models/baseoperator.py", line 424, in wrapper
    return func(self, *args, **kwargs)
  File "/home/ashok/miniconda3/envs/mysecondenvironment/lib/python3.8/site-packages/airflow/operators/python.py", line 238, in execute
    return_value = self.execute_callable()
  File "/home/ashok/miniconda3/envs/mysecondenvironment/lib/python3.8/site-packages/airflow/operators/python.py", line 256, in execute_callable
    return runner.run(*self.op_args, **self.op_kwargs)
  File "/home/ashok/miniconda3/envs/mysecondenvironment/lib/python3.8/site-packages/airflow/utils/operator_helpers.py", line 252, in run
    return self.func(*args, **kwargs)
  File "/home/ashok/mlops_project/airflow/dags/mlops_diabetes_pipeline.py", line 442, in log_model_mlflow
    mlflow.set_experiment(MLFLOW_EXPERIMENT)
  File "/home/ashok/miniconda3/envs/mysecondenvironment/lib/python3.8/site-packages/mlflow/tracking/fluent.py", line 145, in set_experiment
    experiment = client.get_experiment_by_name(experiment_name)
  File "/home/ashok/miniconda3/envs/mysecondenvironment/lib/python3.8/site-packages/mlflow/tracking/client.py", line 1256, in get_experiment_by_name
    return self._tracking_client.get_experiment_by_name(name)
  File "/home/ashok/miniconda3/envs/mysecondenvironment/lib/python3.8/site-packages/mlflow/tracking/_tracking_service/client.py", line 501, in get_experiment_by_name
    return self.store.get_experiment_by_name(name)
  File "/home/ashok/miniconda3/envs/mysecondenvironment/lib/python3.8/site-packages/mlflow/store/tracking/rest_store.py", line 519, in get_experiment_by_name
    response_proto = self._call_endpoint(GetExperimentByName, req_body)
  File "/home/ashok/miniconda3/envs/mysecondenvironment/lib/python3.8/site-packages/mlflow/store/tracking/rest_store.py", line 82, in _call_endpoint
    return call_endpoint(self.get_host_creds(), endpoint, method, json_body, response_proto)
  File "/home/ashok/miniconda3/envs/mysecondenvironment/lib/python3.8/site-packages/mlflow/utils/rest_utils.py", line 365, in call_endpoint
    response = http_request(**call_kwargs)
  File "/home/ashok/miniconda3/envs/mysecondenvironment/lib/python3.8/site-packages/mlflow/utils/rest_utils.py", line 212, in http_request
    raise MlflowException(f"API request to {url} failed with exception {e}")
mlflow.exceptions.MlflowException: API request to http://localhost:5000/api/2.0/mlflow/experiments/get-by-name failed with exception HTTPConnectionPool(host='localhost', port=5000): Max retries exceeded with url: /api/2.0/mlflow/experiments/get-by-name?experiment_name=diabetes_mlops_experiment (Caused by ResponseError('too many 500 error responses'))
[2025-09-05T11:43:36.024+0545] {logging_mixin.py:190} INFO - Task instance in failure state
[2025-09-05T11:43:36.024+0545] {logging_mixin.py:190} INFO - Task start:2025-09-05 05:57:35.083486+00:00 end:2025-09-05 05:58:36.023721+00:00 duration:60.940235
[2025-09-05T11:43:36.025+0545] {logging_mixin.py:190} INFO - Task:<Task(PythonOperator): log_model_mlflow> dag:<DAG: mlops_diabetes_pipeline> dagrun:<DagRun mlops_diabetes_pipeline @ 2025-09-05 05:56:45.402705+00:00: manual__2025-09-05T05:56:45.402705+00:00, state:running, queued_at: 2025-09-05 05:56:45.422634+00:00. externally triggered: True>
[2025-09-05T11:43:36.025+0545] {logging_mixin.py:190} INFO - Failure caused by API request to http://localhost:5000/api/2.0/mlflow/experiments/get-by-name failed with exception HTTPConnectionPool(host='localhost', port=5000): Max retries exceeded with url: /api/2.0/mlflow/experiments/get-by-name?experiment_name=diabetes_mlops_experiment (Caused by ResponseError('too many 500 error responses'))
[2025-09-05T11:43:36.025+0545] {taskinstance.py:1226} INFO - Marking task as UP_FOR_RETRY. dag_id=mlops_diabetes_pipeline, task_id=log_model_mlflow, run_id=manual__2025-09-05T05:56:45.402705+00:00, execution_date=20250905T055645, start_date=20250905T055735, end_date=20250905T055836
[2025-09-05T11:43:36.041+0545] {base.py:84} INFO - Retrieving connection 'smtp_default'
[2025-09-05T11:43:36.041+0545] {email.py:272} INFO - Email alerting: attempt 1
[2025-09-05T11:43:37.712+0545] {email.py:283} INFO - Sent an alert email to ['koiralaashok02@gmail.com']
[2025-09-05T11:43:40.426+0545] {taskinstance.py:341} INFO - ::group::Post task execution logs
[2025-09-05T11:43:40.427+0545] {standard_task_runner.py:124} ERROR - Failed to execute job 380 for task log_model_mlflow (API request to http://localhost:5000/api/2.0/mlflow/experiments/get-by-name failed with exception HTTPConnectionPool(host='localhost', port=5000): Max retries exceeded with url: /api/2.0/mlflow/experiments/get-by-name?experiment_name=diabetes_mlops_experiment (Caused by ResponseError('too many 500 error responses')); 47600)
Traceback (most recent call last):
  File "/home/ashok/miniconda3/envs/mysecondenvironment/lib/python3.8/site-packages/requests/adapters.py", line 667, in send
    resp = conn.urlopen(
  File "/home/ashok/miniconda3/envs/mysecondenvironment/lib/python3.8/site-packages/urllib3/connectionpool.py", line 897, in urlopen
    return self.urlopen(
  File "/home/ashok/miniconda3/envs/mysecondenvironment/lib/python3.8/site-packages/urllib3/connectionpool.py", line 897, in urlopen
    return self.urlopen(
  File "/home/ashok/miniconda3/envs/mysecondenvironment/lib/python3.8/site-packages/urllib3/connectionpool.py", line 897, in urlopen
    return self.urlopen(
  [Previous line repeated 2 more times]
  File "/home/ashok/miniconda3/envs/mysecondenvironment/lib/python3.8/site-packages/urllib3/connectionpool.py", line 887, in urlopen
    retries = retries.increment(method, url, response=response, _pool=self)
  File "/home/ashok/miniconda3/envs/mysecondenvironment/lib/python3.8/site-packages/urllib3/util/retry.py", line 594, in increment
    raise MaxRetryError(_pool, url, error or ResponseError(cause))
urllib3.exceptions.MaxRetryError: HTTPConnectionPool(host='localhost', port=5000): Max retries exceeded with url: /api/2.0/mlflow/experiments/get-by-name?experiment_name=diabetes_mlops_experiment (Caused by ResponseError('too many 500 error responses'))

During handling of the above exception, another exception occurred:

Traceback (most recent call last):
  File "/home/ashok/miniconda3/envs/mysecondenvironment/lib/python3.8/site-packages/mlflow/utils/rest_utils.py", line 189, in http_request
    return _get_http_response_with_retries(
  File "/home/ashok/miniconda3/envs/mysecondenvironment/lib/python3.8/site-packages/mlflow/utils/request_utils.py", line 237, in _get_http_response_with_retries
    return session.request(method, url, allow_redirects=allow_redirects, **kwargs)
  File "/home/ashok/miniconda3/envs/mysecondenvironment/lib/python3.8/site-packages/requests/sessions.py", line 589, in request
    resp = self.send(prep, **send_kwargs)
  File "/home/ashok/miniconda3/envs/mysecondenvironment/lib/python3.8/site-packages/requests/sessions.py", line 703, in send
    r = adapter.send(request, **kwargs)
  File "/home/ashok/miniconda3/envs/mysecondenvironment/lib/python3.8/site-packages/requests/adapters.py", line 691, in send
    raise RetryError(e, request=request)
requests.exceptions.RetryError: HTTPConnectionPool(host='localhost', port=5000): Max retries exceeded with url: /api/2.0/mlflow/experiments/get-by-name?experiment_name=diabetes_mlops_experiment (Caused by ResponseError('too many 500 error responses'))

During handling of the above exception, another exception occurred:

Traceback (most recent call last):
  File "/home/ashok/miniconda3/envs/mysecondenvironment/lib/python3.8/site-packages/airflow/task/task_runner/standard_task_runner.py", line 117, in _start_by_fork
    ret = args.func(args, dag=self.dag)
  File "/home/ashok/miniconda3/envs/mysecondenvironment/lib/python3.8/site-packages/airflow/cli/cli_config.py", line 49, in command
    return func(*args, **kwargs)
  File "/home/ashok/miniconda3/envs/mysecondenvironment/lib/python3.8/site-packages/airflow/utils/cli.py", line 116, in wrapper
    return f(*args, **kwargs)
  File "/home/ashok/miniconda3/envs/mysecondenvironment/lib/python3.8/site-packages/airflow/cli/commands/task_command.py", line 483, in task_run
    task_return_code = _run_task_by_selected_method(args, _dag, ti)
  File "/home/ashok/miniconda3/envs/mysecondenvironment/lib/python3.8/site-packages/airflow/cli/commands/task_command.py", line 256, in _run_task_by_selected_method
    return _run_raw_task(args, ti)
  File "/home/ashok/miniconda3/envs/mysecondenvironment/lib/python3.8/site-packages/airflow/cli/commands/task_command.py", line 341, in _run_raw_task
    return ti._run_raw_task(
  File "/home/ashok/miniconda3/envs/mysecondenvironment/lib/python3.8/site-packages/airflow/utils/session.py", line 97, in wrapper
    return func(*args, session=session, **kwargs)
  File "/home/ashok/miniconda3/envs/mysecondenvironment/lib/python3.8/site-packages/airflow/models/taskinstance.py", line 3006, in _run_raw_task
    return _run_raw_task(
  File "/home/ashok/miniconda3/envs/mysecondenvironment/lib/python3.8/site-packages/airflow/models/taskinstance.py", line 274, in _run_raw_task
    TaskInstance._execute_task_with_callbacks(
  File "/home/ashok/miniconda3/envs/mysecondenvironment/lib/python3.8/site-packages/airflow/models/taskinstance.py", line 3161, in _execute_task_with_callbacks
    result = self._execute_task(context, task_orig)
  File "/home/ashok/miniconda3/envs/mysecondenvironment/lib/python3.8/site-packages/airflow/models/taskinstance.py", line 3185, in _execute_task
    return _execute_task(self, context, task_orig)
  File "/home/ashok/miniconda3/envs/mysecondenvironment/lib/python3.8/site-packages/airflow/models/taskinstance.py", line 768, in _execute_task
    result = _execute_callable(context=context, **execute_callable_kwargs)
  File "/home/ashok/miniconda3/envs/mysecondenvironment/lib/python3.8/site-packages/airflow/models/taskinstance.py", line 734, in _execute_callable
    return ExecutionCallableRunner(
  File "/home/ashok/miniconda3/envs/mysecondenvironment/lib/python3.8/site-packages/airflow/utils/operator_helpers.py", line 252, in run
    return self.func(*args, **kwargs)
  File "/home/ashok/miniconda3/envs/mysecondenvironment/lib/python3.8/site-packages/airflow/models/baseoperator.py", line 424, in wrapper
    return func(self, *args, **kwargs)
  File "/home/ashok/miniconda3/envs/mysecondenvironment/lib/python3.8/site-packages/airflow/operators/python.py", line 238, in execute
    return_value = self.execute_callable()
  File "/home/ashok/miniconda3/envs/mysecondenvironment/lib/python3.8/site-packages/airflow/operators/python.py", line 256, in execute_callable
    return runner.run(*self.op_args, **self.op_kwargs)
  File "/home/ashok/miniconda3/envs/mysecondenvironment/lib/python3.8/site-packages/airflow/utils/operator_helpers.py", line 252, in run
    return self.func(*args, **kwargs)
  File "/home/ashok/mlops_project/airflow/dags/mlops_diabetes_pipeline.py", line 442, in log_model_mlflow
    mlflow.set_experiment(MLFLOW_EXPERIMENT)
  File "/home/ashok/miniconda3/envs/mysecondenvironment/lib/python3.8/site-packages/mlflow/tracking/fluent.py", line 145, in set_experiment
    experiment = client.get_experiment_by_name(experiment_name)
  File "/home/ashok/miniconda3/envs/mysecondenvironment/lib/python3.8/site-packages/mlflow/tracking/client.py", line 1256, in get_experiment_by_name
    return self._tracking_client.get_experiment_by_name(name)
  File "/home/ashok/miniconda3/envs/mysecondenvironment/lib/python3.8/site-packages/mlflow/tracking/_tracking_service/client.py", line 501, in get_experiment_by_name
    return self.store.get_experiment_by_name(name)
  File "/home/ashok/miniconda3/envs/mysecondenvironment/lib/python3.8/site-packages/mlflow/store/tracking/rest_store.py", line 519, in get_experiment_by_name
    response_proto = self._call_endpoint(GetExperimentByName, req_body)
  File "/home/ashok/miniconda3/envs/mysecondenvironment/lib/python3.8/site-packages/mlflow/store/tracking/rest_store.py", line 82, in _call_endpoint
    return call_endpoint(self.get_host_creds(), endpoint, method, json_body, response_proto)
  File "/home/ashok/miniconda3/envs/mysecondenvironment/lib/python3.8/site-packages/mlflow/utils/rest_utils.py", line 365, in call_endpoint
    response = http_request(**call_kwargs)
  File "/home/ashok/miniconda3/envs/mysecondenvironment/lib/python3.8/site-packages/mlflow/utils/rest_utils.py", line 212, in http_request
    raise MlflowException(f"API request to {url} failed with exception {e}")
mlflow.exceptions.MlflowException: API request to http://localhost:5000/api/2.0/mlflow/experiments/get-by-name failed with exception HTTPConnectionPool(host='localhost', port=5000): Max retries exceeded with url: /api/2.0/mlflow/experiments/get-by-name?experiment_name=diabetes_mlops_experiment (Caused by ResponseError('too many 500 error responses'))
[2025-09-05T11:43:40.610+0545] {local_task_job_runner.py:266} INFO - Task exited with return code 1
[2025-09-05T11:43:40.626+0545] {taskinstance.py:3901} INFO - 0 downstream tasks scheduled from follow-on schedule check
[2025-09-05T11:43:40.626+0545] {local_task_job_runner.py:245} INFO - ::endgroup::
