[2025-09-04T09:48:14.886+0545] {local_task_job_runner.py:123} INFO - ::group::Pre task execution logs
[2025-09-04T09:48:14.896+0545] {taskinstance.py:2614} INFO - Dependencies all met for dep_context=non-requeueable deps ti=<TaskInstance: mlops_diabetes_pipeline.data_drift manual__2025-09-04T04:02:14.339977+00:00 [queued]>
[2025-09-04T09:48:14.900+0545] {taskinstance.py:2614} INFO - Dependencies all met for dep_context=requeueable deps ti=<TaskInstance: mlops_diabetes_pipeline.data_drift manual__2025-09-04T04:02:14.339977+00:00 [queued]>
[2025-09-04T09:48:14.900+0545] {taskinstance.py:2867} INFO - Starting attempt 1 of 1
[2025-09-04T09:48:14.917+0545] {taskinstance.py:2890} INFO - Executing <Task(PythonOperator): data_drift> on 2025-09-04 04:02:14.339977+00:00
[2025-09-04T09:48:14.934+0545] {standard_task_runner.py:72} INFO - Started process 29878 to run task
[2025-09-04T09:48:14.940+0545] {standard_task_runner.py:104} INFO - Running: ['airflow', 'tasks', 'run', 'mlops_diabetes_pipeline', 'data_drift', 'manual__2025-09-04T04:02:14.339977+00:00', '--job-id', '28', '--raw', '--subdir', 'DAGS_FOLDER/mlops_diabetes_pipeline.py', '--cfg-path', '/tmp/tmpql8hvs0y']
[2025-09-04T09:48:14.940+0545] {standard_task_runner.py:105} INFO - Job 28: Subtask data_drift
[2025-09-04T09:48:14.980+0545] {task_command.py:467} INFO - Running <TaskInstance: mlops_diabetes_pipeline.data_drift manual__2025-09-04T04:02:14.339977+00:00 [running]> on host ashok-Nitro-ANV16-41
[2025-09-04T09:48:15.035+0545] {taskinstance.py:3134} INFO - Exporting env vars: AIRFLOW_CTX_DAG_OWNER='airflow' AIRFLOW_CTX_DAG_ID='mlops_diabetes_pipeline' AIRFLOW_CTX_TASK_ID='data_drift' AIRFLOW_CTX_EXECUTION_DATE='2025-09-04T04:02:14.339977+00:00' AIRFLOW_CTX_TRY_NUMBER='1' AIRFLOW_CTX_DAG_RUN_ID='manual__2025-09-04T04:02:14.339977+00:00'
[2025-09-04T09:48:15.036+0545] {logging_mixin.py:190} INFO - Task instance is in running state
[2025-09-04T09:48:15.037+0545] {logging_mixin.py:190} INFO -  Previous state of the Task instance: queued
[2025-09-04T09:48:15.037+0545] {logging_mixin.py:190} INFO - Current task name:data_drift state:running start_date:2025-09-04 04:03:14.896853+00:00
[2025-09-04T09:48:15.037+0545] {logging_mixin.py:190} INFO - Dag name:mlops_diabetes_pipeline and current dag run status:running
[2025-09-04T09:48:15.037+0545] {taskinstance.py:732} INFO - ::endgroup::
[2025-09-04T09:48:16.487+0545] {taskinstance.py:3313} ERROR - Task failed with exception
Traceback (most recent call last):
  File "/home/ashok/miniconda3/envs/mysecondenvironment/lib/python3.8/site-packages/sqlalchemy/engine/base.py", line 1910, in _execute_context
    self.dialect.do_execute(
  File "/home/ashok/miniconda3/envs/mysecondenvironment/lib/python3.8/site-packages/sqlalchemy/engine/default.py", line 736, in do_execute
    cursor.execute(statement, parameters)
  File "/home/ashok/miniconda3/envs/mysecondenvironment/lib/python3.8/site-packages/pymysql/cursors.py", line 148, in execute
    result = self._query(query)
  File "/home/ashok/miniconda3/envs/mysecondenvironment/lib/python3.8/site-packages/pymysql/cursors.py", line 310, in _query
    conn.query(q)
  File "/home/ashok/miniconda3/envs/mysecondenvironment/lib/python3.8/site-packages/pymysql/connections.py", line 548, in query
    self._affected_rows = self._read_query_result(unbuffered=unbuffered)
  File "/home/ashok/miniconda3/envs/mysecondenvironment/lib/python3.8/site-packages/pymysql/connections.py", line 775, in _read_query_result
    result.read()
  File "/home/ashok/miniconda3/envs/mysecondenvironment/lib/python3.8/site-packages/pymysql/connections.py", line 1156, in read
    first_packet = self.connection._read_packet()
  File "/home/ashok/miniconda3/envs/mysecondenvironment/lib/python3.8/site-packages/pymysql/connections.py", line 725, in _read_packet
    packet.raise_for_error()
  File "/home/ashok/miniconda3/envs/mysecondenvironment/lib/python3.8/site-packages/pymysql/protocol.py", line 221, in raise_for_error
    err.raise_mysql_exception(self._data)
  File "/home/ashok/miniconda3/envs/mysecondenvironment/lib/python3.8/site-packages/pymysql/err.py", line 143, in raise_mysql_exception
    raise errorclass(errno, errval)
pymysql.err.ProgrammingError: (1146, "Table 'diabetes_ml.predictions_auto' doesn't exist")

The above exception was the direct cause of the following exception:

Traceback (most recent call last):
  File "/home/ashok/miniconda3/envs/mysecondenvironment/lib/python3.8/site-packages/airflow/models/taskinstance.py", line 768, in _execute_task
    result = _execute_callable(context=context, **execute_callable_kwargs)
  File "/home/ashok/miniconda3/envs/mysecondenvironment/lib/python3.8/site-packages/airflow/models/taskinstance.py", line 734, in _execute_callable
    return ExecutionCallableRunner(
  File "/home/ashok/miniconda3/envs/mysecondenvironment/lib/python3.8/site-packages/airflow/utils/operator_helpers.py", line 252, in run
    return self.func(*args, **kwargs)
  File "/home/ashok/miniconda3/envs/mysecondenvironment/lib/python3.8/site-packages/airflow/models/baseoperator.py", line 424, in wrapper
    return func(self, *args, **kwargs)
  File "/home/ashok/miniconda3/envs/mysecondenvironment/lib/python3.8/site-packages/airflow/operators/python.py", line 238, in execute
    return_value = self.execute_callable()
  File "/home/ashok/miniconda3/envs/mysecondenvironment/lib/python3.8/site-packages/airflow/operators/python.py", line 256, in execute_callable
    return runner.run(*self.op_args, **self.op_kwargs)
  File "/home/ashok/miniconda3/envs/mysecondenvironment/lib/python3.8/site-packages/airflow/utils/operator_helpers.py", line 252, in run
    return self.func(*args, **kwargs)
  File "/home/ashok/mlops_project/monitoring/data_drift_monitor.py", line 21, in monitor_data_drift
    cur_df = pd.read_sql(f"SELECT * FROM {PREDICTIONS_TABLE}", con=engine)
  File "/home/ashok/miniconda3/envs/mysecondenvironment/lib/python3.8/site-packages/pandas/io/sql.py", line 663, in read_sql
    return pandas_sql.read_query(
  File "/home/ashok/miniconda3/envs/mysecondenvironment/lib/python3.8/site-packages/pandas/io/sql.py", line 1738, in read_query
    result = self.execute(sql, params)
  File "/home/ashok/miniconda3/envs/mysecondenvironment/lib/python3.8/site-packages/pandas/io/sql.py", line 1562, in execute
    return self.con.exec_driver_sql(sql, *args)
  File "/home/ashok/miniconda3/envs/mysecondenvironment/lib/python3.8/site-packages/sqlalchemy/engine/base.py", line 1770, in exec_driver_sql
    return self._exec_driver_sql(
  File "/home/ashok/miniconda3/envs/mysecondenvironment/lib/python3.8/site-packages/sqlalchemy/engine/base.py", line 1674, in _exec_driver_sql
    ret = self._execute_context(
  File "/home/ashok/miniconda3/envs/mysecondenvironment/lib/python3.8/site-packages/sqlalchemy/engine/base.py", line 1953, in _execute_context
    self._handle_dbapi_exception(
  File "/home/ashok/miniconda3/envs/mysecondenvironment/lib/python3.8/site-packages/sqlalchemy/engine/base.py", line 2134, in _handle_dbapi_exception
    util.raise_(
  File "/home/ashok/miniconda3/envs/mysecondenvironment/lib/python3.8/site-packages/sqlalchemy/util/compat.py", line 211, in raise_
    raise exception
  File "/home/ashok/miniconda3/envs/mysecondenvironment/lib/python3.8/site-packages/sqlalchemy/engine/base.py", line 1910, in _execute_context
    self.dialect.do_execute(
  File "/home/ashok/miniconda3/envs/mysecondenvironment/lib/python3.8/site-packages/sqlalchemy/engine/default.py", line 736, in do_execute
    cursor.execute(statement, parameters)
  File "/home/ashok/miniconda3/envs/mysecondenvironment/lib/python3.8/site-packages/pymysql/cursors.py", line 148, in execute
    result = self._query(query)
  File "/home/ashok/miniconda3/envs/mysecondenvironment/lib/python3.8/site-packages/pymysql/cursors.py", line 310, in _query
    conn.query(q)
  File "/home/ashok/miniconda3/envs/mysecondenvironment/lib/python3.8/site-packages/pymysql/connections.py", line 548, in query
    self._affected_rows = self._read_query_result(unbuffered=unbuffered)
  File "/home/ashok/miniconda3/envs/mysecondenvironment/lib/python3.8/site-packages/pymysql/connections.py", line 775, in _read_query_result
    result.read()
  File "/home/ashok/miniconda3/envs/mysecondenvironment/lib/python3.8/site-packages/pymysql/connections.py", line 1156, in read
    first_packet = self.connection._read_packet()
  File "/home/ashok/miniconda3/envs/mysecondenvironment/lib/python3.8/site-packages/pymysql/connections.py", line 725, in _read_packet
    packet.raise_for_error()
  File "/home/ashok/miniconda3/envs/mysecondenvironment/lib/python3.8/site-packages/pymysql/protocol.py", line 221, in raise_for_error
    err.raise_mysql_exception(self._data)
  File "/home/ashok/miniconda3/envs/mysecondenvironment/lib/python3.8/site-packages/pymysql/err.py", line 143, in raise_mysql_exception
    raise errorclass(errno, errval)
sqlalchemy.exc.ProgrammingError: (pymysql.err.ProgrammingError) (1146, "Table 'diabetes_ml.predictions_auto' doesn't exist")
[SQL: SELECT * FROM predictions_auto]
(Background on this error at: https://sqlalche.me/e/14/f405)
[2025-09-04T09:48:16.496+0545] {logging_mixin.py:190} INFO - Task instance in failure state
[2025-09-04T09:48:16.496+0545] {logging_mixin.py:190} INFO - Task start:2025-09-04 04:03:14.896853+00:00 end:2025-09-04 04:03:16.495805+00:00 duration:1.598952
[2025-09-04T09:48:16.496+0545] {logging_mixin.py:190} INFO - Task:<Task(PythonOperator): data_drift> dag:<DAG: mlops_diabetes_pipeline> dagrun:<DagRun mlops_diabetes_pipeline @ 2025-09-04 04:02:14.339977+00:00: manual__2025-09-04T04:02:14.339977+00:00, state:running, queued_at: 2025-09-04 04:02:14.356173+00:00. externally triggered: True>
[2025-09-04T09:48:16.496+0545] {logging_mixin.py:190} INFO - Failure caused by (pymysql.err.ProgrammingError) (1146, "Table 'diabetes_ml.predictions_auto' doesn't exist")
[SQL: SELECT * FROM predictions_auto]
(Background on this error at: https://sqlalche.me/e/14/f405)
[2025-09-04T09:48:16.496+0545] {taskinstance.py:1226} INFO - Marking task as FAILED. dag_id=mlops_diabetes_pipeline, task_id=data_drift, run_id=manual__2025-09-04T04:02:14.339977+00:00, execution_date=20250904T040214, start_date=20250904T040314, end_date=20250904T040316
[2025-09-04T09:48:16.519+0545] {taskinstance.py:341} INFO - ::group::Post task execution logs
[2025-09-04T09:48:16.520+0545] {standard_task_runner.py:124} ERROR - Failed to execute job 28 for task data_drift ((pymysql.err.ProgrammingError) (1146, "Table 'diabetes_ml.predictions_auto' doesn't exist")
[SQL: SELECT * FROM predictions_auto]
(Background on this error at: https://sqlalche.me/e/14/f405); 29878)
Traceback (most recent call last):
  File "/home/ashok/miniconda3/envs/mysecondenvironment/lib/python3.8/site-packages/sqlalchemy/engine/base.py", line 1910, in _execute_context
    self.dialect.do_execute(
  File "/home/ashok/miniconda3/envs/mysecondenvironment/lib/python3.8/site-packages/sqlalchemy/engine/default.py", line 736, in do_execute
    cursor.execute(statement, parameters)
  File "/home/ashok/miniconda3/envs/mysecondenvironment/lib/python3.8/site-packages/pymysql/cursors.py", line 148, in execute
    result = self._query(query)
  File "/home/ashok/miniconda3/envs/mysecondenvironment/lib/python3.8/site-packages/pymysql/cursors.py", line 310, in _query
    conn.query(q)
  File "/home/ashok/miniconda3/envs/mysecondenvironment/lib/python3.8/site-packages/pymysql/connections.py", line 548, in query
    self._affected_rows = self._read_query_result(unbuffered=unbuffered)
  File "/home/ashok/miniconda3/envs/mysecondenvironment/lib/python3.8/site-packages/pymysql/connections.py", line 775, in _read_query_result
    result.read()
  File "/home/ashok/miniconda3/envs/mysecondenvironment/lib/python3.8/site-packages/pymysql/connections.py", line 1156, in read
    first_packet = self.connection._read_packet()
  File "/home/ashok/miniconda3/envs/mysecondenvironment/lib/python3.8/site-packages/pymysql/connections.py", line 725, in _read_packet
    packet.raise_for_error()
  File "/home/ashok/miniconda3/envs/mysecondenvironment/lib/python3.8/site-packages/pymysql/protocol.py", line 221, in raise_for_error
    err.raise_mysql_exception(self._data)
  File "/home/ashok/miniconda3/envs/mysecondenvironment/lib/python3.8/site-packages/pymysql/err.py", line 143, in raise_mysql_exception
    raise errorclass(errno, errval)
pymysql.err.ProgrammingError: (1146, "Table 'diabetes_ml.predictions_auto' doesn't exist")

The above exception was the direct cause of the following exception:

Traceback (most recent call last):
  File "/home/ashok/miniconda3/envs/mysecondenvironment/lib/python3.8/site-packages/airflow/task/task_runner/standard_task_runner.py", line 117, in _start_by_fork
    ret = args.func(args, dag=self.dag)
  File "/home/ashok/miniconda3/envs/mysecondenvironment/lib/python3.8/site-packages/airflow/cli/cli_config.py", line 49, in command
    return func(*args, **kwargs)
  File "/home/ashok/miniconda3/envs/mysecondenvironment/lib/python3.8/site-packages/airflow/utils/cli.py", line 116, in wrapper
    return f(*args, **kwargs)
  File "/home/ashok/miniconda3/envs/mysecondenvironment/lib/python3.8/site-packages/airflow/cli/commands/task_command.py", line 483, in task_run
    task_return_code = _run_task_by_selected_method(args, _dag, ti)
  File "/home/ashok/miniconda3/envs/mysecondenvironment/lib/python3.8/site-packages/airflow/cli/commands/task_command.py", line 256, in _run_task_by_selected_method
    return _run_raw_task(args, ti)
  File "/home/ashok/miniconda3/envs/mysecondenvironment/lib/python3.8/site-packages/airflow/cli/commands/task_command.py", line 341, in _run_raw_task
    return ti._run_raw_task(
  File "/home/ashok/miniconda3/envs/mysecondenvironment/lib/python3.8/site-packages/airflow/utils/session.py", line 97, in wrapper
    return func(*args, session=session, **kwargs)
  File "/home/ashok/miniconda3/envs/mysecondenvironment/lib/python3.8/site-packages/airflow/models/taskinstance.py", line 3006, in _run_raw_task
    return _run_raw_task(
  File "/home/ashok/miniconda3/envs/mysecondenvironment/lib/python3.8/site-packages/airflow/models/taskinstance.py", line 274, in _run_raw_task
    TaskInstance._execute_task_with_callbacks(
  File "/home/ashok/miniconda3/envs/mysecondenvironment/lib/python3.8/site-packages/airflow/models/taskinstance.py", line 3161, in _execute_task_with_callbacks
    result = self._execute_task(context, task_orig)
  File "/home/ashok/miniconda3/envs/mysecondenvironment/lib/python3.8/site-packages/airflow/models/taskinstance.py", line 3185, in _execute_task
    return _execute_task(self, context, task_orig)
  File "/home/ashok/miniconda3/envs/mysecondenvironment/lib/python3.8/site-packages/airflow/models/taskinstance.py", line 768, in _execute_task
    result = _execute_callable(context=context, **execute_callable_kwargs)
  File "/home/ashok/miniconda3/envs/mysecondenvironment/lib/python3.8/site-packages/airflow/models/taskinstance.py", line 734, in _execute_callable
    return ExecutionCallableRunner(
  File "/home/ashok/miniconda3/envs/mysecondenvironment/lib/python3.8/site-packages/airflow/utils/operator_helpers.py", line 252, in run
    return self.func(*args, **kwargs)
  File "/home/ashok/miniconda3/envs/mysecondenvironment/lib/python3.8/site-packages/airflow/models/baseoperator.py", line 424, in wrapper
    return func(self, *args, **kwargs)
  File "/home/ashok/miniconda3/envs/mysecondenvironment/lib/python3.8/site-packages/airflow/operators/python.py", line 238, in execute
    return_value = self.execute_callable()
  File "/home/ashok/miniconda3/envs/mysecondenvironment/lib/python3.8/site-packages/airflow/operators/python.py", line 256, in execute_callable
    return runner.run(*self.op_args, **self.op_kwargs)
  File "/home/ashok/miniconda3/envs/mysecondenvironment/lib/python3.8/site-packages/airflow/utils/operator_helpers.py", line 252, in run
    return self.func(*args, **kwargs)
  File "/home/ashok/mlops_project/monitoring/data_drift_monitor.py", line 21, in monitor_data_drift
    cur_df = pd.read_sql(f"SELECT * FROM {PREDICTIONS_TABLE}", con=engine)
  File "/home/ashok/miniconda3/envs/mysecondenvironment/lib/python3.8/site-packages/pandas/io/sql.py", line 663, in read_sql
    return pandas_sql.read_query(
  File "/home/ashok/miniconda3/envs/mysecondenvironment/lib/python3.8/site-packages/pandas/io/sql.py", line 1738, in read_query
    result = self.execute(sql, params)
  File "/home/ashok/miniconda3/envs/mysecondenvironment/lib/python3.8/site-packages/pandas/io/sql.py", line 1562, in execute
    return self.con.exec_driver_sql(sql, *args)
  File "/home/ashok/miniconda3/envs/mysecondenvironment/lib/python3.8/site-packages/sqlalchemy/engine/base.py", line 1770, in exec_driver_sql
    return self._exec_driver_sql(
  File "/home/ashok/miniconda3/envs/mysecondenvironment/lib/python3.8/site-packages/sqlalchemy/engine/base.py", line 1674, in _exec_driver_sql
    ret = self._execute_context(
  File "/home/ashok/miniconda3/envs/mysecondenvironment/lib/python3.8/site-packages/sqlalchemy/engine/base.py", line 1953, in _execute_context
    self._handle_dbapi_exception(
  File "/home/ashok/miniconda3/envs/mysecondenvironment/lib/python3.8/site-packages/sqlalchemy/engine/base.py", line 2134, in _handle_dbapi_exception
    util.raise_(
  File "/home/ashok/miniconda3/envs/mysecondenvironment/lib/python3.8/site-packages/sqlalchemy/util/compat.py", line 211, in raise_
    raise exception
  File "/home/ashok/miniconda3/envs/mysecondenvironment/lib/python3.8/site-packages/sqlalchemy/engine/base.py", line 1910, in _execute_context
    self.dialect.do_execute(
  File "/home/ashok/miniconda3/envs/mysecondenvironment/lib/python3.8/site-packages/sqlalchemy/engine/default.py", line 736, in do_execute
    cursor.execute(statement, parameters)
  File "/home/ashok/miniconda3/envs/mysecondenvironment/lib/python3.8/site-packages/pymysql/cursors.py", line 148, in execute
    result = self._query(query)
  File "/home/ashok/miniconda3/envs/mysecondenvironment/lib/python3.8/site-packages/pymysql/cursors.py", line 310, in _query
    conn.query(q)
  File "/home/ashok/miniconda3/envs/mysecondenvironment/lib/python3.8/site-packages/pymysql/connections.py", line 548, in query
    self._affected_rows = self._read_query_result(unbuffered=unbuffered)
  File "/home/ashok/miniconda3/envs/mysecondenvironment/lib/python3.8/site-packages/pymysql/connections.py", line 775, in _read_query_result
    result.read()
  File "/home/ashok/miniconda3/envs/mysecondenvironment/lib/python3.8/site-packages/pymysql/connections.py", line 1156, in read
    first_packet = self.connection._read_packet()
  File "/home/ashok/miniconda3/envs/mysecondenvironment/lib/python3.8/site-packages/pymysql/connections.py", line 725, in _read_packet
    packet.raise_for_error()
  File "/home/ashok/miniconda3/envs/mysecondenvironment/lib/python3.8/site-packages/pymysql/protocol.py", line 221, in raise_for_error
    err.raise_mysql_exception(self._data)
  File "/home/ashok/miniconda3/envs/mysecondenvironment/lib/python3.8/site-packages/pymysql/err.py", line 143, in raise_mysql_exception
    raise errorclass(errno, errval)
sqlalchemy.exc.ProgrammingError: (pymysql.err.ProgrammingError) (1146, "Table 'diabetes_ml.predictions_auto' doesn't exist")
[SQL: SELECT * FROM predictions_auto]
(Background on this error at: https://sqlalche.me/e/14/f405)
[2025-09-04T09:48:16.556+0545] {local_task_job_runner.py:266} INFO - Task exited with return code 1
[2025-09-04T09:48:16.566+0545] {taskinstance.py:3901} INFO - 0 downstream tasks scheduled from follow-on schedule check
[2025-09-04T09:48:16.575+0545] {local_task_job_runner.py:245} INFO - ::endgroup::
