[2025-09-04T13:17:25.327+0545] {local_task_job_runner.py:123} INFO - ::group::Pre task execution logs
[2025-09-04T13:17:25.333+0545] {taskinstance.py:2614} INFO - Dependencies all met for dep_context=non-requeueable deps ti=<TaskInstance: mlops_diabetes_pipeline.log_model_mlflow manual__2025-09-04T07:25:16.767269+00:00 [queued]>
[2025-09-04T13:17:25.336+0545] {taskinstance.py:2614} INFO - Dependencies all met for dep_context=requeueable deps ti=<TaskInstance: mlops_diabetes_pipeline.log_model_mlflow manual__2025-09-04T07:25:16.767269+00:00 [queued]>
[2025-09-04T13:17:25.336+0545] {taskinstance.py:2867} INFO - Starting attempt 2 of 2
[2025-09-04T13:17:25.347+0545] {taskinstance.py:2890} INFO - Executing <Task(PythonOperator): log_model_mlflow> on 2025-09-04 07:25:16.767269+00:00
[2025-09-04T13:17:25.359+0545] {standard_task_runner.py:72} INFO - Started process 4786 to run task
[2025-09-04T13:17:25.362+0545] {standard_task_runner.py:104} INFO - Running: ['airflow', 'tasks', 'run', 'mlops_diabetes_pipeline', 'log_model_mlflow', 'manual__2025-09-04T07:25:16.767269+00:00', '--job-id', '111', '--raw', '--subdir', 'DAGS_FOLDER/mlops_diabetes_pipeline.py', '--cfg-path', '/tmp/tmpxfiigsp5']
[2025-09-04T13:17:25.362+0545] {standard_task_runner.py:105} INFO - Job 111: Subtask log_model_mlflow
[2025-09-04T13:17:25.387+0545] {task_command.py:467} INFO - Running <TaskInstance: mlops_diabetes_pipeline.log_model_mlflow manual__2025-09-04T07:25:16.767269+00:00 [running]> on host ashok-Nitro-ANV16-41
[2025-09-04T13:17:25.425+0545] {taskinstance.py:3134} INFO - Exporting env vars: AIRFLOW_CTX_DAG_EMAIL='koiralaashok02@gmail.com' AIRFLOW_CTX_DAG_OWNER='airflow' AIRFLOW_CTX_DAG_ID='mlops_diabetes_pipeline' AIRFLOW_CTX_TASK_ID='log_model_mlflow' AIRFLOW_CTX_EXECUTION_DATE='2025-09-04T07:25:16.767269+00:00' AIRFLOW_CTX_TRY_NUMBER='2' AIRFLOW_CTX_DAG_RUN_ID='manual__2025-09-04T07:25:16.767269+00:00'
[2025-09-04T13:17:25.426+0545] {logging_mixin.py:190} INFO - Task instance is in running state
[2025-09-04T13:17:25.426+0545] {logging_mixin.py:190} INFO -  Previous state of the Task instance: queued
[2025-09-04T13:17:25.426+0545] {logging_mixin.py:190} INFO - Current task name:log_model_mlflow state:running start_date:2025-09-04 07:32:25.333670+00:00
[2025-09-04T13:17:25.426+0545] {logging_mixin.py:190} INFO - Dag name:mlops_diabetes_pipeline and current dag run status:running
[2025-09-04T13:17:25.426+0545] {taskinstance.py:732} INFO - ::endgroup::
[2025-09-04T13:17:25.427+0545] {taskinstance.py:3313} ERROR - Task failed with exception
Traceback (most recent call last):
  File "/home/ashok/miniconda3/envs/mysecondenvironment/lib/python3.8/site-packages/redis/connection.py", line 385, in connect_check_health
    sock = self.retry.call_with_retry(
  File "/home/ashok/miniconda3/envs/mysecondenvironment/lib/python3.8/site-packages/redis/retry.py", line 87, in call_with_retry
    return do()
  File "/home/ashok/miniconda3/envs/mysecondenvironment/lib/python3.8/site-packages/redis/connection.py", line 386, in <lambda>
    lambda: self._connect(), lambda error: self.disconnect(error)
  File "/home/ashok/miniconda3/envs/mysecondenvironment/lib/python3.8/site-packages/redis/connection.py", line 797, in _connect
    raise err
  File "/home/ashok/miniconda3/envs/mysecondenvironment/lib/python3.8/site-packages/redis/connection.py", line 781, in _connect
    sock.connect(socket_address)
ConnectionRefusedError: [Errno 111] Connection refused

During handling of the above exception, another exception occurred:

Traceback (most recent call last):
  File "/home/ashok/miniconda3/envs/mysecondenvironment/lib/python3.8/site-packages/airflow/models/taskinstance.py", line 768, in _execute_task
    result = _execute_callable(context=context, **execute_callable_kwargs)
  File "/home/ashok/miniconda3/envs/mysecondenvironment/lib/python3.8/site-packages/airflow/models/taskinstance.py", line 734, in _execute_callable
    return ExecutionCallableRunner(
  File "/home/ashok/miniconda3/envs/mysecondenvironment/lib/python3.8/site-packages/airflow/utils/operator_helpers.py", line 252, in run
    return self.func(*args, **kwargs)
  File "/home/ashok/miniconda3/envs/mysecondenvironment/lib/python3.8/site-packages/airflow/models/baseoperator.py", line 424, in wrapper
    return func(self, *args, **kwargs)
  File "/home/ashok/miniconda3/envs/mysecondenvironment/lib/python3.8/site-packages/airflow/operators/python.py", line 238, in execute
    return_value = self.execute_callable()
  File "/home/ashok/miniconda3/envs/mysecondenvironment/lib/python3.8/site-packages/airflow/operators/python.py", line 256, in execute_callable
    return runner.run(*self.op_args, **self.op_kwargs)
  File "/home/ashok/miniconda3/envs/mysecondenvironment/lib/python3.8/site-packages/airflow/utils/operator_helpers.py", line 252, in run
    return self.func(*args, **kwargs)
  File "/home/ashok/mlops_project/airflow/dags/mlops_diabetes_pipeline.py", line 401, in log_model_mlflow
    tuned_path_b = r.get(RKEY_TUNED_MODEL_PATH)
  File "/home/ashok/miniconda3/envs/mysecondenvironment/lib/python3.8/site-packages/redis/commands/core.py", line 1829, in get
    return self.execute_command("GET", name, keys=[name])
  File "/home/ashok/miniconda3/envs/mysecondenvironment/lib/python3.8/site-packages/redis/client.py", line 624, in execute_command
    return self._execute_command(*args, **options)
  File "/home/ashok/miniconda3/envs/mysecondenvironment/lib/python3.8/site-packages/redis/client.py", line 630, in _execute_command
    conn = self.connection or pool.get_connection()
  File "/home/ashok/miniconda3/envs/mysecondenvironment/lib/python3.8/site-packages/redis/utils.py", line 188, in wrapper
    return func(*args, **kwargs)
  File "/home/ashok/miniconda3/envs/mysecondenvironment/lib/python3.8/site-packages/redis/connection.py", line 1530, in get_connection
    connection.connect()
  File "/home/ashok/miniconda3/envs/mysecondenvironment/lib/python3.8/site-packages/redis/connection.py", line 379, in connect
    self.connect_check_health(check_health=True)
  File "/home/ashok/miniconda3/envs/mysecondenvironment/lib/python3.8/site-packages/redis/connection.py", line 391, in connect_check_health
    raise ConnectionError(self._error_message(e))
redis.exceptions.ConnectionError: Error 111 connecting to 127.0.0.1:6379. Connection refused.
[2025-09-04T13:17:25.433+0545] {logging_mixin.py:190} INFO - Task instance in failure state
[2025-09-04T13:17:25.433+0545] {logging_mixin.py:190} INFO - Task start:2025-09-04 07:32:25.333670+00:00 end:2025-09-04 07:32:25.432881+00:00 duration:0.099211
[2025-09-04T13:17:25.433+0545] {logging_mixin.py:190} INFO - Task:<Task(PythonOperator): log_model_mlflow> dag:<DAG: mlops_diabetes_pipeline> dagrun:<DagRun mlops_diabetes_pipeline @ 2025-09-04 07:25:16.767269+00:00: manual__2025-09-04T07:25:16.767269+00:00, state:running, queued_at: 2025-09-04 07:25:16.773201+00:00. externally triggered: True>
[2025-09-04T13:17:25.433+0545] {logging_mixin.py:190} INFO - Failure caused by Error 111 connecting to 127.0.0.1:6379. Connection refused.
[2025-09-04T13:17:25.433+0545] {taskinstance.py:1226} INFO - Marking task as FAILED. dag_id=mlops_diabetes_pipeline, task_id=log_model_mlflow, run_id=manual__2025-09-04T07:25:16.767269+00:00, execution_date=20250904T072516, start_date=20250904T073225, end_date=20250904T073225
[2025-09-04T13:17:25.440+0545] {base.py:84} INFO - Retrieving connection 'smtp_default'
[2025-09-04T13:17:25.440+0545] {email.py:272} INFO - Email alerting: attempt 1
[2025-09-04T13:17:57.543+0545] {email.py:283} INFO - Sent an alert email to ['koiralaashok02@gmail.com']
[2025-09-04T13:17:59.658+0545] {taskinstance.py:341} INFO - ::group::Post task execution logs
[2025-09-04T13:17:59.658+0545] {standard_task_runner.py:124} ERROR - Failed to execute job 111 for task log_model_mlflow (Error 111 connecting to 127.0.0.1:6379. Connection refused.; 4786)
Traceback (most recent call last):
  File "/home/ashok/miniconda3/envs/mysecondenvironment/lib/python3.8/site-packages/redis/connection.py", line 385, in connect_check_health
    sock = self.retry.call_with_retry(
  File "/home/ashok/miniconda3/envs/mysecondenvironment/lib/python3.8/site-packages/redis/retry.py", line 87, in call_with_retry
    return do()
  File "/home/ashok/miniconda3/envs/mysecondenvironment/lib/python3.8/site-packages/redis/connection.py", line 386, in <lambda>
    lambda: self._connect(), lambda error: self.disconnect(error)
  File "/home/ashok/miniconda3/envs/mysecondenvironment/lib/python3.8/site-packages/redis/connection.py", line 797, in _connect
    raise err
  File "/home/ashok/miniconda3/envs/mysecondenvironment/lib/python3.8/site-packages/redis/connection.py", line 781, in _connect
    sock.connect(socket_address)
ConnectionRefusedError: [Errno 111] Connection refused

During handling of the above exception, another exception occurred:

Traceback (most recent call last):
  File "/home/ashok/miniconda3/envs/mysecondenvironment/lib/python3.8/site-packages/airflow/task/task_runner/standard_task_runner.py", line 117, in _start_by_fork
    ret = args.func(args, dag=self.dag)
  File "/home/ashok/miniconda3/envs/mysecondenvironment/lib/python3.8/site-packages/airflow/cli/cli_config.py", line 49, in command
    return func(*args, **kwargs)
  File "/home/ashok/miniconda3/envs/mysecondenvironment/lib/python3.8/site-packages/airflow/utils/cli.py", line 116, in wrapper
    return f(*args, **kwargs)
  File "/home/ashok/miniconda3/envs/mysecondenvironment/lib/python3.8/site-packages/airflow/cli/commands/task_command.py", line 483, in task_run
    task_return_code = _run_task_by_selected_method(args, _dag, ti)
  File "/home/ashok/miniconda3/envs/mysecondenvironment/lib/python3.8/site-packages/airflow/cli/commands/task_command.py", line 256, in _run_task_by_selected_method
    return _run_raw_task(args, ti)
  File "/home/ashok/miniconda3/envs/mysecondenvironment/lib/python3.8/site-packages/airflow/cli/commands/task_command.py", line 341, in _run_raw_task
    return ti._run_raw_task(
  File "/home/ashok/miniconda3/envs/mysecondenvironment/lib/python3.8/site-packages/airflow/utils/session.py", line 97, in wrapper
    return func(*args, session=session, **kwargs)
  File "/home/ashok/miniconda3/envs/mysecondenvironment/lib/python3.8/site-packages/airflow/models/taskinstance.py", line 3006, in _run_raw_task
    return _run_raw_task(
  File "/home/ashok/miniconda3/envs/mysecondenvironment/lib/python3.8/site-packages/airflow/models/taskinstance.py", line 274, in _run_raw_task
    TaskInstance._execute_task_with_callbacks(
  File "/home/ashok/miniconda3/envs/mysecondenvironment/lib/python3.8/site-packages/airflow/models/taskinstance.py", line 3161, in _execute_task_with_callbacks
    result = self._execute_task(context, task_orig)
  File "/home/ashok/miniconda3/envs/mysecondenvironment/lib/python3.8/site-packages/airflow/models/taskinstance.py", line 3185, in _execute_task
    return _execute_task(self, context, task_orig)
  File "/home/ashok/miniconda3/envs/mysecondenvironment/lib/python3.8/site-packages/airflow/models/taskinstance.py", line 768, in _execute_task
    result = _execute_callable(context=context, **execute_callable_kwargs)
  File "/home/ashok/miniconda3/envs/mysecondenvironment/lib/python3.8/site-packages/airflow/models/taskinstance.py", line 734, in _execute_callable
    return ExecutionCallableRunner(
  File "/home/ashok/miniconda3/envs/mysecondenvironment/lib/python3.8/site-packages/airflow/utils/operator_helpers.py", line 252, in run
    return self.func(*args, **kwargs)
  File "/home/ashok/miniconda3/envs/mysecondenvironment/lib/python3.8/site-packages/airflow/models/baseoperator.py", line 424, in wrapper
    return func(self, *args, **kwargs)
  File "/home/ashok/miniconda3/envs/mysecondenvironment/lib/python3.8/site-packages/airflow/operators/python.py", line 238, in execute
    return_value = self.execute_callable()
  File "/home/ashok/miniconda3/envs/mysecondenvironment/lib/python3.8/site-packages/airflow/operators/python.py", line 256, in execute_callable
    return runner.run(*self.op_args, **self.op_kwargs)
  File "/home/ashok/miniconda3/envs/mysecondenvironment/lib/python3.8/site-packages/airflow/utils/operator_helpers.py", line 252, in run
    return self.func(*args, **kwargs)
  File "/home/ashok/mlops_project/airflow/dags/mlops_diabetes_pipeline.py", line 401, in log_model_mlflow
    tuned_path_b = r.get(RKEY_TUNED_MODEL_PATH)
  File "/home/ashok/miniconda3/envs/mysecondenvironment/lib/python3.8/site-packages/redis/commands/core.py", line 1829, in get
    return self.execute_command("GET", name, keys=[name])
  File "/home/ashok/miniconda3/envs/mysecondenvironment/lib/python3.8/site-packages/redis/client.py", line 624, in execute_command
    return self._execute_command(*args, **options)
  File "/home/ashok/miniconda3/envs/mysecondenvironment/lib/python3.8/site-packages/redis/client.py", line 630, in _execute_command
    conn = self.connection or pool.get_connection()
  File "/home/ashok/miniconda3/envs/mysecondenvironment/lib/python3.8/site-packages/redis/utils.py", line 188, in wrapper
    return func(*args, **kwargs)
  File "/home/ashok/miniconda3/envs/mysecondenvironment/lib/python3.8/site-packages/redis/connection.py", line 1530, in get_connection
    connection.connect()
  File "/home/ashok/miniconda3/envs/mysecondenvironment/lib/python3.8/site-packages/redis/connection.py", line 379, in connect
    self.connect_check_health(check_health=True)
  File "/home/ashok/miniconda3/envs/mysecondenvironment/lib/python3.8/site-packages/redis/connection.py", line 391, in connect_check_health
    raise ConnectionError(self._error_message(e))
redis.exceptions.ConnectionError: Error 111 connecting to 127.0.0.1:6379. Connection refused.
[2025-09-04T13:17:59.675+0545] {local_task_job_runner.py:266} INFO - Task exited with return code 1
[2025-09-04T13:17:59.683+0545] {taskinstance.py:3901} INFO - 0 downstream tasks scheduled from follow-on schedule check
[2025-09-04T13:17:59.692+0545] {local_task_job_runner.py:245} INFO - ::endgroup::
